<?xml version="1.0" encoding="UTF-8"?>
<!-- Generated by org.testng.reporters.JUnitReportReporter -->
<testsuite hostname="MayankHP" failures="0" tests="1" name="demo1.ExpectedExceptionExample" time="0.001" errors="1" timestamp="2022-05-07T20:13:27 EDT" skipped="0">
  <testcase classname="demo1.ExpectedExceptionExample" name="checkResult" time="0.001">
    <error message="
Method ExpectedExceptionExample.checkResult()[pri:0, instance:demo1.ExpectedExceptionExample@53142455] should have thrown an exception of type class java.lang.ArithmeticException" type="org.testng.TestException">
      <![CDATA[org.testng.TestException: 
Method ExpectedExceptionExample.checkResult()[pri:0, instance:demo1.ExpectedExceptionExample@53142455] should have thrown an exception of type class java.lang.ArithmeticException
at org.testng.internal.invokers.ExpectedExceptionsHolder.noException(ExpectedExceptionsHolder.java:81)
at org.testng.internal.invokers.TestInvoker.considerExceptions(TestInvoker.java:853)
at org.testng.internal.invokers.TestInvoker.invokeMethod(TestInvoker.java:714)
at org.testng.internal.invokers.TestInvoker.invokeTestMethod(TestInvoker.java:220)
at org.testng.internal.invokers.MethodRunner.runInSequence(MethodRunner.java:50)
at org.testng.internal.invokers.TestInvoker$MethodInvocationAgent.invoke(TestInvoker.java:945)
at org.testng.internal.invokers.TestInvoker.invokeTestMethods(TestInvoker.java:193)
at org.testng.internal.invokers.TestMethodWorker.invokeTestMethods(TestMethodWorker.java:146)
at org.testng.internal.invokers.TestMethodWorker.run(TestMethodWorker.java:128)
at java.base/java.util.ArrayList.forEach(ArrayList.java:1541)
at org.testng.TestRunner.privateRun(TestRunner.java:808)
at org.testng.TestRunner.run(TestRunner.java:603)
at org.testng.SuiteRunner.runTest(SuiteRunner.java:429)
at org.testng.SuiteRunner.runSequentially(SuiteRunner.java:423)
at org.testng.SuiteRunner.privateRun(SuiteRunner.java:383)
at org.testng.SuiteRunner.run(SuiteRunner.java:326)
at org.testng.SuiteRunnerWorker.runSuite(SuiteRunnerWorker.java:52)
at org.testng.SuiteRunnerWorker.run(SuiteRunnerWorker.java:95)
at org.testng.TestNG.runSuitesSequentially(TestNG.java:1249)
at org.testng.TestNG.runSuitesLocally(TestNG.java:1169)
at org.testng.TestNG.runSuites(TestNG.java:1092)
at org.testng.TestNG.run(TestNG.java:1060)
at org.testng.remote.AbstractRemoteTestNG.run(AbstractRemoteTestNG.java:115)
at org.testng.remote.RemoteTestNG.initAndRun(RemoteTestNG.java:251)
at org.testng.remote.RemoteTestNG.main(RemoteTestNG.java:77)
]]>
    </error>
  </testcase> <!-- checkResult -->
  <system-out/>
</testsuite> <!-- demo1.ExpectedExceptionExample -->
